Workbook

Sheet Year
B1: Groceries | C1: Eating Out | D1: Car | E1: Bills | F1: Other | H1: Totals
A2: January | B2: =January!B36 -> 51.1 | C2: =January!C36 -> 110.63 | D2: =January!D36 -> 41.79 | E2: =January!E36 -> 700.97 | F2: =January!G36 -> 194.02 | H2: =SUM(B2:F2) -> 1098.51
A3: February | B3: =February!B44 -> 67.35 | C3: =February!C44 -> 293.79 | D3: =February!D44 -> 60.16 | E3: =February!E44 -> 715.96 | F3: =February!G44 -> 267.47 | H3: =SUM(B3:F3) -> 1404.73
A4: March | B4: =March!B46 -> 257.29 | C4: =March!C46 -> 401.85 | D4: =March!D46 -> 111.32 | E4: =March!E46 -> 1010.47 | F4: =March!G46 -> 403.83 | H4: =SUM(B4:F4) -> 2184.76
A5: April | B5: =April!B45 -> 146.68 | C5: =April!C45 -> 335.07 | D5: =April!D45 -> 166.98 | E5: =April!E45 -> 698.26 | F5: =April!G45 -> 398.11 | H5: =SUM(B5:F5) -> 1745.1
A6: May | B6: =May!B39 -> 190.1 | C6: =May!C39 -> 213.07 | D6: =May!D39 -> 41.8 | E6: =May!E39 -> 795.95 | F6: =May!G39 -> 454.65 | H6: =SUM(B6:F6) -> 1695.57
A7: June | B7: =June!B46 -> 105.37 | C7: =June!C46 -> 290.31 | D7: =June!D46 -> 136.02 | E7: =June!E46 -> 793.44 | F7: =June!G46 -> 215.99 | H7: =SUM(B7:F7) -> 1541.13
A8: July | B8: =July!B47 -> 142.61 | C8: =July!C47 -> 410.16 | D8: =July!D47 -> 158.42 | E8: =July!E47 -> 842.51 | F8: =July!G47 -> 402.45 | H8: =SUM(B8:F8) -> 1956.15
A9: August | B9: =August!B43 -> 206.52 | C9: =August!C43 -> 266.96 | D9: =August!D43 -> 198.61 | E9: =August!E43 -> 841.59 | F9: =August!G43 -> 221.11 | H9: =SUM(B9:F9) -> 1734.79
A10: September | B10: =September!B45 -> 46.78 | C10: =September!C45 -> 340.49 | D10: =September!D45 -> 46.96 | E10: =September!E45 -> 832.33 | F10: =September!G45 -> 624.08 | H10: =SUM(B10:F10) -> 1890.64
A11: October | B11: =October!B42 -> 67.89 | C11: =October!C42 -> 332.76 | D11: =October!D42 -> 22.55 | E11: =October!E42 -> 886.35 | F11: =October!G42 -> 1012.88 | H11: =SUM(B11:F11) -> 2322.43
A12: November | B12: =November!B34 -> 115 | C12: =November!C34 -> 333.08 | D12: =November!D34 -> 47.61 | E12: =November!E34 -> 693.36 | F12: =November!G34 -> 439.58 | H12: =SUM(B12:F12) -> 1628.63
A13: December | B13: =December!B34 -> 196.06 | C13: =December!C34 -> 392.72 | D13: =December!D34 -> 115.75 | E13: =December!E34 -> 809.14 | F13: =December!G34 -> 255.09 | H13: =SUM(B13:F13) -> 1768.76
A15: Totals | B15: =SUM(B2:B13) -> 1592.75 | C15: =SUM(C2:C13) -> 3720.89 | D15: =SUM(D2:D13) -> 1147.97 | E15: =SUM(E2:E13) -> 9620.33 | F15: =SUM(F2:F13) -> 4889.26 | H15: =SUM(B15:F15) -> 20971.2
A17: Averages | B17: =QUOTIENT(SUM(B2:B13),12) -> 132 | C17: =QUOTIENT(SUM(C2:C13),12) -> 310 | D17: =QUOTIENT(SUM(D2:D13),12) -> 95 | E17: =QUOTIENT(SUM(E2:E13),12) -> 801 | F17: =QUOTIENT(SUM(F2:F13),12) -> 407 | H17: =QUOTIENT(H15,12) -> 1747

Sheet January
B1: Groceries | C1: Eating Out | D1: Car | E1: Bills | G1: Other
A2: 43101 | E2: 44.99 | F2: internet
A3: 43102 | E3: 9.99 | F3: spotify
A4: 43103 | C4: 16 | E4: 70 | F4: phone
A5: 43104 | B5: 7.49 | E5: 565 | F5: rent
A6: 43105 | C6: 14
A7: 43106 | C7: 5.5
A8: 43107
A9: 43108 | G9: 10 | H9: Climbers Coalition
A10: 43109
A11: 43110 | G11: 28.91 | H11: Bullet Journal
A12: 43111
A13: 43112 | B13: 24.14 | G13: 12.27 | H13: Toys
A14: 43113 | G14: 5 | H14: Not Sure
A15: 43114
A16: 43115 | D16: 39.79
A17: 43116 | G17: 30.81 | H17: Books 4 School
A18: 43117 | B18: 12.48
A19: 43118 | D19: 2
A20: 43119 | G20: 15 | H20: Griz Card
A21: 43120
A22: 43121 | C22: 11 | G22: 8.78 | H22: Hardware Stuff
C23: 8.13
A24: 43122 | G24: 27 | H24: Strings
A25: 43123 | G25: 56.25 | H25: More School Books
A26: 43124 | C26: 11
A27: 43125
A28: 43126 | E28: 10.99 | F28: Amazon Prime
A29: 43127 | B29: 6.99
A30: 43128
A31: 43129
A32: 43130 | C32: 10
C33: 15
A34: 43131 | C34: 20
A36: totals | B36: 51.1 | C36: 110.63 | D36: 41.79 | E36: 700.97 | G36: 194.02

Sheet February
B1: Groceries | C1: Eating Out | D1: Car | E1: Bills | G1: Other
A2: 43132 | C2: 7.45 | E2: 9.99 | F2: Spotify
E3: 67 | F3: Phone
A4: 43133 | C4: 10 | E4: 565 | F4: Rent
A5: 43134
A6: 43135
A7: 43136 | C7: 5
A8: 43137 | C8: 12 | G8: 11 | H8: towels at the U
G9: 15.49 | H9: walgreens?
A10: 43138 | C10: 16.65 | D10: 20
A11: 43139 | B11: 6.39 | C11: 7.95
C12: 10
A13: 43140 | B13: 7.78 | C13: 7
A14: 43141
A15: 43142
A16: 43143 | C16: 11 | E16: 44.99 | F16: internet
C17: 5.5
C18: 12
C19: 16
C20: 10
A21: 43144 | C21: 14
A22: 43145 | C22: 16
A23: 43146 | C23: 10
A24: 43147 | C24: 30
A25: 43148 | C25: 5
A26: 43149
A27: 43150 | D27: 40.16
A28: 43151 | G28: 66.99 | H28: harness
G29: 143.99 | H29: shoes
A30: 43152 | C30: 10
A31: 43153
A32: 43154 | C32: 3
C33: 21
A34: 43155 | C34: 9.85 | E34: 15.99 | F34: spotify
A35: 43156
A36: 43157 | C36: 9 | E36: 12.99 | F36: Amazon Prime
C37: 3
A38: 43158 | C38: 7.45
A39: 43159 | B39: 53.18 | C39: 8.75 | G39: 30 | H39: Paula Bauer
C40: 16.19
...

Sheet March
B1: Groceries | C1: Eating Out | D1: Car | E1: Bills | G1: Other
B2: Groceries | C2: Eating out | D2: Car | E2: Bills | G2: Other
A3: 43160 | E3: 565 | F3: rent
A4: 43161 | C4: 12.95
C5: 18
A6: 43162
A7: 43163 | G7: 29.98 | H7: toys?
A8: 43164 | B8: 3.69 | C8: 14.4 | E8: 6 | F8: BOA Credit card
B9: 5.5 | C9: 7.5 | E9: 67 | F9: Phone
C10: 25
A11: 43165 | C11: 17.5
A12: 43166 | E12: 44.99 | F12: Internet
A13: 43167 | C13: 8.5 | G13: 79.3 | H13: Run To The Pub
C14: 12.95 | G14: 20 | H14: Selway Bitterroot?
A15: 43168 | B15: 19.15 | C15: 9 | E15: 50 | F15: YNAB | G15: 5.99 | H15: Ace Hardware
A16: 43169
A17: 43170 | B17: 24.2 | C17: 9
C18: 17.5
A19: 43171 | C19: 10
C20: 5.35
A21: 43172 | B21: 46.85 | C21: 12.95 | G21: 115.57 | H21: Punch Brothers Concert
C22: 7.24 | G22: 77.25 | H22: Run race
C23: 12 | G23: 2 | H23: School Supplies
A24: 43173 | C24: 4.25 | D24: 26.54
A25: 43174 | G25: 33 | H25: strings
A26: 43175 | B26: 45.04
A27: 43176
A28: 43177 | C28: 40
A29: 43178 | C29: 28.8 | D29: 2
C30: 20
C31: 9.25
A32: 43179
A33: 43180 | B33: 8.79
A34: 43181 | B34: 12.86 | C34: 7 | E34: 82 | F34: taxes
A35: 43182 | C35: 19 | D35: 38.94
A36: 43183 | B36: 28.22 | C36: 11.23 | D36: 43.84 | E36: 14.99 | F36: Spotify
A37: 43184
A38: 43185 | C38: 6.75 | E38: 12.99 | F38: Amazon Prime
C39: 11.29
A40: 43186
...

Sheet April
B1: Groceries | C1: Eating Out | D1: Car | E1: Bills | G1: Other
A2: 43191 | E2: 565 | F2: rent | G2: 15.99 | H2: Not sure
A3: 43192 | C3: 21 | D3: 40.42
A4: 43193 | B4: 10.98 | D4: 28.42
A5: 43194 | C5: 11.45 | E5: 12.99 | F5: Amazon Prime | G5: 79.2 | H5: Liquor
A6: 43195
A7: 43196
A8: 43197 | C8: 15.54 | G8: 4.58 | H8: Amazon Something
C9: 10
A10: 43198 | B10: 19.36 | E10: 2.29 | F10: Meds
A11: 43199 | D11: 40.15 | E11: 44.99 | F11: Internet | G11: 19.95 | H11: Shirt for Stephanie
A12: 43200 | B12: 14.96 | C12: 21 | E12: 60 | F12: Phone Bill
A13: 43201 | G13: 32.01 | H13: Stickers
A14: 43202 | B14: 19.92
A15: 43203 | C15: 14.94
A16: 43204 | C16: 12 | G16: 6.98 | H16: Sim card adaptors
A17: 43205 | C17: 9.5
A18: 43206 | C18: 5 | G18: 14.99 | H18: Amazon Something
A19: 43207 | C19: 11.44
A20: 43208 | C20: 8.44 | D20: 3
C21: 10
A22: 43209 | B22: 14.99 | C22: 9
C23: 13.5
A24: 43210 | C24: 10
C25: 14.94
C26: 22
A27: 43211 | B27: 8.99 | C27: 19.38
B28: 1.15
A29: 43212 | B29: 44.01 | D29: 40
A30: 43213 | C30: 6 | D30: 14.99 | G30: 18.67 | H30: Pen
C31: 10
A32: 43214
A33: 43215 | C33: 5.5
C34: 6
A35: 43216 | E35: 12.99 | F35: Amazon Prime | G35: 62.95 | H35: cash withdrawl
A36: 43217 | C36: 11
C37: 10
A38: 43218 | C38: 16.19
C39: 17
C40: 5.25
...

Sheet May
B1: Groceries | C1: Eating Out | D1: Car | E1: Bills | G1: Other
A2: 43221 | E2: 565 | F2: rent
A3: 43222 | B3: 43.18 | C3: 10
A4: 43223 | C4: 15.25 | G4: 31.35 | H4: Liquor
A5: 43224 | C5: 14 | E5: 12.99 | F5: Amazon Prime
A6: 43225
A7: 43226
A8: 43227 | C8: 21
A9: 43228
A10: 43229 | C10: 9.38 | G10: 135 | H10: tripod
C11: 14
A12: 43230 | B12: 1.79 | C12: 16
A13: 43231 | B13: 17.76 | C13: 7
A14: 43232 | B14: 17.07
A15: 43233 | G15: 80.39 | H15: Beard
G16: 18.74 | H16: Don't remember
A17: 43234 | C17: 17.25
A18: 43235 | B18: 33.59
A19: 43236 | B19: 46.21 | C19: 8 | G19: 30 | H19: haircut
B20: 3.99
A21: 43237 | C21: 5.49 | E21: 44.99 | F21: Internet
E22: 50 | F22: BOA Credit card
A23: 43238
A24: 43239
A25: 43240 | C25: 25
A26: 43241 | G26: 5 | H26: Craigslist post
G27: 59.37 | H27: Raspberry Pi
A28: 43242 | G28: 75.75 | H28: School Books
A29: 43243 | B29: 26.51 | E29: 14.99 | F29: Spotify
A30: 43244 | D30: 40.8
A31: 43245 | D31: 1
A32: 43246 | C32: 10 | E32: 12.99 | F32: Amazon Prime
A33: 43247 | C33: 3.9
A34: 43248 | C34: 14.6 | G34: 15.96 | H34: Ace Hardware
A35: 43249 | C35: 15.7 | E35: 50 | F35: Phone Bill | G35: 3.09 | H35: Gas Station
A36: 43250
A37: 43251 | C37: 6.5 | E37: 44.99 | F37: Internet
A39: totals | B39: 190.1 | C39: 213.07 | D39: 41.8 | E39: 795.95 | G39: 454.65

Sheet June
B1: Groceries | C1: Eating Out | D1: Car | E1: Bills | G1: Other
A2: 43252 | C2: 10 | E2: 44.99 | F2: Internet
A3: 43253
A4: 43254 | D4: 46.69
A5: 43255 | D5: 33.11 | E5: 12.99 | F5: Amazon Prime
A6: 43256 | E6: 90.96 | F6: Health Insurace
A7: 43257 | E7: 565 | F7: Rent
A8: 43258 | G8: 16.5 | H8: Amazon purchase
A9: 43259 | B9: 6.98
A10: 43260
A11: 43261
A12: 43262 | C12: 10
A13: 43263 | G13: 77 | H13: Textbook
A14: 43264 | G14: 6.98 | H14: Shantaram
A15: 43265 | C15: 13.5 | D15: 3.5
A16: 43266 | C16: 12
A17: 43267 | B17: 1.05 | C17: 7 | G17: 25 | H17: Elliott GoFundMe
A18: 43268 | C18: 8.75
A19: 43269 | B19: 26.95 | C19: 9.23 | D19: 43.72
A20: 43270 | B20: 8.38 | C20: 20.09 | E20: 51.52 | F20: Car Insurance
C21: 15
A22: 43271 | C22: 6 | D22: 4.5
C23: 8.95
C24: 9.6
G25: 21.22 | H25: Concert Ticket
A26: 43272 | B26: 23.97 | C26: 13 | G26: 53.34 | H26: Pandemic
B27: 31.7 | C27: 8.1
A28: 43273 | C28: 5 | D28: 4.5 | G28: 13.95 | H28: Map
A29: 43274
A30: 43275
A31: 43276 | B31: 1.69 | C31: 8.95 | E31: 14.99 | F31: Spotify
C32: 9
C33: 15
C34: 11
C35: 6.5
A36: 43277 | C36: 15.54 | E36: 12.99 | F36: Amazon Prime
A37: 43278 | B37: 4.65 | C37: 13 | G37: 2 | H37: Paper
A38: 43279 | C38: 17.1
C39: 27
A40: 43280
...

Sheet July
B1: Groceries | C1: Eating Out | D1: Car | E1: Bills | G1: Other
A2: 43282 | C2: 4.25
A3: 43283 | B3: 20.49 | C3: 15 | D3: 63.49 | E3: 565 | F3: Rent | G3: <--(See D3) | H3: Oil Change
B4: 35.51 | C4: 14.31
A5: 43284 | D5: 2 | E5: 90.96 | F5: Health Insurance | G5: 254.51 | H5: Truck Registration
A6: 43285 | C6: 7 | E6: 12.99 | F6: Amazon Prime | G6: 28.99 | H6: Picture for Sdawg
A7: 43286
A8: 43287 | C8: 8.5
C9: 10
A10: 43288 | C10: 6
C11: 5
A12: 43289 | C12: 6.5
A13: 43290 | B13: 36.82 | C13: 9 | G13: 10 | H13: Bike Derailleur Hanger
C14: 13
C15: 28
C16: 17.81
A17: 43291
A18: 43292 | C18: 18.75
A19: 43293 | E19: 62.04 | F19: Phone Bill
A20: 43294 | D20: 4.5
A21: 43295 | C21: 8.75 | D21: 45.31
A22: 43296
A23: 43297 | B23: 9.99 | E23: 44.99 | F23: Internet
B24: 5.88
B25: 15.88
A26: 43298 | C26: 16.19
A27: 43299 | C27: 19 | E27: 51.54 | F27: Insurance | G27: 14.69 | H27: School Supplies
A28: 43300 | G28: 44.2 | H28: Haircut
A29: 43301 | C29: 13.69
A30: 43302 | C30: 11.5 | D30: 21.56
A31: 43303 | B31: 5 | C31: 1.02
C32: 18.5
A33: 43304 | C33: 14.5 | D33: 21.56 | G33: 38.3 | H33: Lights
A34: 43305 | B34: 5 | C34: 1.02 | E34: 14.99 | F34: Spotify
C35: 22.5
A36: 43306 | B36: 1.05 | C36: 14.92
C37: 4
A38: 43307 | G38: 11.76 | H38: Drivers License
A39: 43308 | B39: 4.6
A40: 43309 | C40: 23
...

Sheet August
B1: Groceries | C1: Eating Out | D1: Car | E1: Bills | G1: Other
A2: 43313 | B2: 8.01 | E2: 90.96 | F2: Insurance
B3: 1.99 | E3: 565 | F3: Rent
B4: 33.87
A5: 43314 | B5: 70.92
A6: 43315 | E6: 10.24 | F6: Erin Mingrone
A7: 43316 | C7: 7 | E7: 62.03 | F7: Phone Bill | G7: 14.98 | H7: Bike tubes
A8: 43317 | B8: 12.98 | C8: 29.33 | D8: 43.88
C9: 5.03
A10: 43318 | C10: 24.98 | D10: 48.83
A11: 43319
A12: 43320 | B12: 6.38 | C12: 14.34
A13: 43321 | C13: 14 | D13: 20.53
C14: 9
A15: 43322 | B15: 13.16 | C15: 10.5
A16: 43323 | B16: 13.11 | C16: 1.99 | D16: 40.5 | G16: 13.98 | H16: Bike Repair
A17: 43324 | C17: 21
C18: 11
A19: 43325 | C19: 6.48 | D19: 44.87 | G19: 7.99 | H19: Vitamins
C20: 3.25 | G20: 99.66 | H20: Gear
C21: 19
A22: 43326 | C22: 10 | G22: 40.57 | H22: Shakey Graves
A23: 43327 | B23: 20.24 | C23: 14 | G23: 4.99 | H23: Sunscreen
C24: 10.2 | G24: 2 | H24: paper
A25: 43328 | C25: 6 | E25: 44.99 | F25: Internet | G25: 16.94 | H25: Phone
A26: 43329 | C26: 3.98 | E26: 53.38 | F26: Car Insurance
A27: 43330
A28: 43331
A29: 43332 | B29: 25.16 | C29: 3.25
A30: 43333
A31: 43334
A32: 43335 | C32: 11
A33: 43336 | C33: 5.99
A34: 43337 | C34: 10.64
C35: 4
A36: 43338 | E36: 14.99 | F36: Spotify
A37: 43339 | C37: 8
A38: 43340 | C38: 3
A39: 43341
A40: 43342
...

Sheet September
B1: Groceries | C1: Eating Out | D1: Car | E1: Bills | G1: Other
A2: 43344 | C2: 15.54 | E2: 565 | F2: rent | G2: 162.5 | H2: School books
A3: 43345
A4: 43346 | C4: 20
A5: 43347 | B5: 15.89 | C5: 14
C6: 15.25
A7: 43348 | C7: 14.5
C8: 4
A9: 43349 | E9: 90.96 | F9: Health Insurance
A10: 43350 | G10: 4 | H10: Bday card
A11: 43351 | C11: 18
C12: 10
C13: 6
A14: 43352
A15: 43353 | C15: 19 | E15: 63 | F15: Phone bill | G15: 10 | H15: Notebook
C16: 6.75 | G16: 102 | H16: Climbing gear
A17: 43354 | C17: 10
A18: 43355
A19: 43356 | C19: 14.5 | G19: 260 | H19: Guitar and amp
A20: 43357 | C20: 13 | G20: 25.12 | H20: Bullshit ATM fees
A21: 43358 | G21: 7.5 | H21: Parking at U
G22: 20.96 | H22: School Supplies/ Planner
A23: 43359 | G23: 3 | H23: Parking at U
A24: 43360 | E24: 59.99 | F24: internet | G24: 25 | H24: Overdraft fee
A25: 43361 | E25: 53.38 | F25: Car insurance
A26: 43362 | B26: 8.12 | C26: 19.74
A27: 43363 | C27: 3
A28: 43364 | C28: 10.95 | G28: 4 | H28: Bday card
A29: 43365 | C29: 8.49
A30: 43366
A31: 43367 | C31: 14
C32: 13.14
A33: 43368
A34: 43369 | C34: 9.9
A35: 43370 | C35: 14
A36: 43371 | B36: 13.2 | C36: 2.85
B37: 9.57
A38: 43372 | C38: 12.5
C39: 18
A40: 43373 | C40: 5.43 | D40: 46.96
...

Sheet October
B1: Groceries | C1: Eating Out | D1: Car | E1: Bills | G1: Other
A2: 43374 | B2: 3.85 | C2: 21.6
C3: 8.95
A4: 43375 | E4: 565 | F4: rent
A5: 43376 | C5: 12.54 | E5: 14.99 | F5: Spotify
A6: 43377 | C6: 14.97 | G6: 8.38 | H6: Portfolio
A7: 43378 | C7: 4 | D7: 1 | G7: 1.5 | H7: interest
D8: 3
A9: 43379
A10: 43380
A11: 43381
A12: 43382
A13: 43383 | C13: 8.32 | G13: 36 | H13: Trip Parking fee
C14: 10
A15: 43384 | C15: 17.34
C16: 20
A17: 43385
A18: 43386
A19: 43387
A20: 43388 | C20: 10.95
C21: 15.98
A22: 43389 | E22: 59.99 | F22: Internet
A23: 43390 | C23: 6 | G23: 18 | H23: Climbing Gym yoga
A24: 43391 | C24: 15.54 | E24: 53.38 | F24: Car insurance
C25: 11
A26: 43392 | B26: 4.99
A27: 43393 | C27: 10
A28: 43394
A29: 43395 | B29: 22.73 | C29: 14.1 | D29: 18.55
A30: 43396 | C30: 6
C31: 4
A32: 43397 | B32: 6.98 | C32: 12.95 | E32: 14.99 | F32: spotify again?
B33: 5.49
A34: 43398 | B34: =5.49+6.98 -> 12.47 | C34: =6+15.54 -> 21.54
A35: 43399
A36: 43400 | C36: =14.94+9 -> 23.94 | G36: 799 | H36: Laptop
A37: 43401 | E37: 178 | F37: Insurance - 2 months | G37: 150 | H37: Helmet
A38: 43402 | C38: =13+27.5+5.5 -> 46
A39: 43403
A40: 43404 | B40: 11.38 | C40: 17.04
...

Sheet November
B1: Groceries | C1: Eating Out | D1: Car | E1: Bills | G1: Other
A2: 43405 | G2: 18 | H2: Climbing
A3: 43406 | B3: 9.5 | C3: 16.39
A4: 43407 | C4: =10+16.74+4 -> 30.74
A5: 43408
A6: 43409 | C6: 15 | E6: 565 | F6: Rent | G6: 22.47 | H6: Games
A7: 43410 | C7: =18+19.8+3.5 -> 41.3 | G7: 60 | H7: Music Supplies
A8: 43411
A9: 43412 | G9: 54 | H9: MaD Parking fee
A10: 43413 | C10: 6.25
A11: 43414 | C11: =15.54+10 -> 25.54 | G11: 18 | H11: Climbing
A12: 43415 | C12: 4 | G12: 6 | H12: Transcripts
A13: 43416 | B13: =8.99+15.64 -> 24.63 | C13: =7+5 -> 12 | G13: 28.43 | H13: Banff
A14: 43417 | B14: 8.99 | C14: 10
C15: 6
A16: 43418 | C16: 4.25 | G16: 18 | H16: Climbing
A17: 43419 | B17: 31.36 | C17: =16.14+4.5+10 -> 30.64 | G17: 14.98 | H17: Mouse
A18: 43420 | C18: 8.95 | E18: 59.99 | F18: Internet | G18: 43.5 | H18: Alpinism Training
A19: 43421 | B19: 6.99 | G19: 18 | H19: Climbing
A20: 43422
A21: 43423 | C21: =7.97+4.75 -> 12.72 | G21: 19.95 | H21: Journal
A22: 43424 | C22: 14 | E22: 53.38 | F22: Insurance
A23: 43425 | C23: =14.94+14.4 -> 29.34
A24: 43426
A25: 43427 | B25: 12.87 | C25: =14+4.5 -> 18.5 | D25: 46.61 | G25: 23.75 | H25: Taxi
A26: 43428 | B26: 9.99
A27: 43429 | C27: 10
A28: 43430 | C28: 13 | E28: 14.99 | F28: Spotify
A29: 43431
A30: 43432 | B30: 10.98 | C30: 3.25 | G30: 112.5 | H30: Helmet and Goggles
A31: 43433 | B31: 9.19 | C31: 15.6
A32: 43434 | C32: =10+12 -> 22 | D32: 1
A34: Totals | B34: =SUM(B4:B32) -> 115 | C34: =SUM(C4:C32) -> 333.08 | D34: =SUM(D4:D32) -> 47.61 | E34: =SUM(E4:E32) -> 693.36 | G34: =SUM(G4:G32) -> 439.58

Sheet December
B1: Groceries | C1: Eating Out | D1: Car | E1: Bills | G1: Other
A2: 43435 | C2: 15.95 | E2: 0.99 | F2: Spotify
A3: 43436
A4: 43437 | C4: 16.25 | E4: 89 | F4: Health Insurance
A5: 43438 | D5: 30.92 | E5: 565 | F5: Rent | G5: 14.99 | H5: Game
A6: 43439 | E6: 54.84 | F6: Phone Bill, Nov + Dec
A7: 43440 | G7: 50.98 | H7: Toy
A8: 43441 | B8: 20.46 | C8: 5 | G8: 29.99 | H8: Alarm Clock
A9: 43442 | B9: 29.52 | C9: =10.25+6.5 -> 16.75 | G9: =10.35+25 -> 35.35 | H9: Service Fees
A10: 43443 | B10: 3.99 | C10: 14 | G10: 8.5 | H10: Cards
A11: 43444 | C11: =8.13+13.25 -> 21.38 | G11: 27.5 | H11: Haircut
A12: 43445
A13: 43446 | B13: 31.9 | C13: 16.14
A14: 43447 | B14: 4.39
A15: 43448 | B15: 7.38
A16: 43449 | C16: =5.25+5.5+22.12 -> 32.87 | G16: 15.99 | H16: Game
A17: 43450
A18: 43451 | B18: =5+21.98 -> 26.98 | C18: =10+10.17 -> 20.17 | E18: 59.99 | F18: Internet | G18: 40 | H18: Happy lamp
A19: 43452 | C19: =10+7.5 -> 17.5 | E19: 39.32 | F19: Insurance
A20: 43453 | B20: =8.56+16.85 -> 25.41 | C20: =11+2.35+4.39 -> 17.74 | D20: =38.83+19.29 -> 58.12 | G20: 9.99 | H20: Game
A21: 43454 | G21: 21.8 | H21: Hat/ Christmas pres
A22: 43455 | C22: =3.25 + 19.08 + 4.5 + 11 -> 37.83
A23: 43456
A24: 43457
A25: 43458 | B25: 28.5 | C25: =17.52 + 2.6 -> 20.12
A26: 43459
A27: 43460 | B27: 17.53 | C27: =22 + 7 -> 29
A28: 43461 | C28: 2.49 | D28: 26.71
A29: 43462 | C29: =10.35+35.75 -> 46.1
A30: 43463 | C30: =8 + 8.24 -> 16.24
A31: 43464
A32: 43465 | C32: =27.48 + 19.2 + 24.15 + 8.56 -> 79.39
A34: Totals | B34: =SUM(B5:B32) -> 196.06 | C34: =SUM(C5:C32) -> 392.72 | D34: =SUM(D5:D32) -> 115.75 | E34: =SUM(E2:E32) -> 809.14 | G34: =SUM(G5:G32) -> 255.09

Sheet Sheet14
A1: D
